<?xml version="1.0" encoding="utf-8"?>
<!-- This URDF was automatically created by SolidWorks to URDF Exporter! Originally created by Stephen Brawner (brawner@gmail.com) 
     Commit Version: 1.5.1-0-g916b5db  Build Version: 1.5.7152.31018
     For more information, please see http://wiki.ros.org/sw_urdf_exporter -->
<robot
  name="tracked_robot">
  <link
    name="Body">
    <inertial>
      <origin
        xyz="-0.010027 -8.6049E-17 0.0028761"
        rpy="0 0 0" />
      <mass
        value="10.232" />
      <inertia
        ixx="0.06036"
        ixy="8.2655E-18"
        ixz="0.0041194"
        iyy="0.3165"
        iyz="-2.6287E-17"
        izz="0.36791" />
    </inertial>
    <visual>
      <origin
        xyz="0 0 0"
        rpy="0 0 0" />
      <geometry>
        <mesh
          filename="package://tracked_robot/meshes/Body.STL" />
      </geometry>
      <material
        name="">
        <color
          rgba="0.79216 0.81961 0.93333 1" />
      </material>
    </visual>
    <collision>
      <origin
        xyz="0 0 0"
        rpy="0 0 0" />
      <geometry>
        <mesh
          filename="package://tracked_robot/meshes/Body.STL" />
      </geometry>
    </collision>
  </link>
  <link
    name="Track_L">
    <inertial>
      <origin
        xyz="0.0068793 0.015459 5.5859E-17"
        rpy="0 0 0" />
      <mass
        value="2.192" />
      <inertia
        ixx="0.0021286"
        ixy="-0.00029468"
        ixz="5.8301E-18"
        iyy="0.090248"
        iyz="6.3661E-20"
        izz="0.088479" />
    </inertial>
    <visual>
      <origin
        xyz="0 0 0"
        rpy="0 0 0" />
      <geometry>
        <mesh
          filename="package://tracked_robot/meshes/Track_L.STL" />
      </geometry>
      <material
        name="">
        <color
          rgba="0.75294 0.75294 0.75294 1" />
      </material>
    </visual>
    <collision>
      <origin
        xyz="0 0 0"
        rpy="0 0 0" />
      <geometry>
        <mesh
          filename="package://tracked_robot/meshes/Track_L.STL" />
      </geometry>
    </collision>
  </link>
  <joint
    name="Fixed_L"
    type="fixed">
    <origin
      xyz="0 0.125 0"
      rpy="0 0 0" />
    <parent
      link="Body" />
    <child
      link="Track_L" />
    <axis
      xyz="0 0 0" />
  </joint>
  <link
    name="Flipper_L">
    <inertial>
      <origin
        xyz="0.12763 0.012498 3.6304E-07"
        rpy="0 0 0" />
      <mass
        value="0.75702" />
      <inertia
        ixx="0.00048991"
        ixy="-1.7332E-07"
        ixz="3.6502E-08"
        iyy="0.008777"
        iyz="-3.2985E-09"
        izz="0.0083653" />
    </inertial>
    <visual>
      <origin
        xyz="0 0 0"
        rpy="0 0 0" />
      <geometry>
        <mesh
          filename="package://tracked_robot/meshes/Flipper_L.STL" />
      </geometry>
      <material
        name="">
        <color
          rgba="0.75294 0.75294 0.75294 1" />
      </material>
    </visual>
    <collision>
      <origin
        xyz="0 0 0"
        rpy="0 0 0" />
      <geometry>
        <mesh
          filename="package://tracked_robot/meshes/Flipper_L.STL" />
      </geometry>
    </collision>
  </link>
  <joint
    name="Joint_L"
    type="continuous">
    <origin
      xyz="0.3 0.04 0"
      rpy="0 0 0" />
    <parent
      link="Track_L" />
    <child
      link="Flipper_L" />
    <axis
      xyz="0 1 0" />
    <limit
      effort="10000"
      velocity="0" />
  </joint>
  <link
    name="Track_R">
    <inertial>
      <origin
        xyz="0.0068793 -0.015459 5.6728E-17"
        rpy="0 0 0" />
      <mass
        value="2.192" />
      <inertia
        ixx="0.0021286"
        ixy="0.00029468"
        ixz="6.504E-18"
        iyy="0.090248"
        iyz="1.2401E-19"
        izz="0.088479" />
    </inertial>
    <visual>
      <origin
        xyz="0 0 0"
        rpy="0 0 0" />
      <geometry>
        <mesh
          filename="package://tracked_robot/meshes/Track_R.STL" />
      </geometry>
      <material
        name="">
        <color
          rgba="0.75294 0.75294 0.75294 1" />
      </material>
    </visual>
    <collision>
      <origin
        xyz="0 0 0"
        rpy="0 0 0" />
      <geometry>
        <mesh
          filename="package://tracked_robot/meshes/Track_R.STL" />
      </geometry>
    </collision>
  </link>
  <joint
    name="Fixed_R"
    type="fixed">
    <origin
      xyz="0 -0.125 0"
      rpy="0 0 0" />
    <parent
      link="Body" />
    <child
      link="Track_R" />
    <axis
      xyz="0 0 0" />
  </joint>
  <link
    name="Flipper_R">
    <inertial>
      <origin
        xyz="0.127654132514173 -0.0124962607498206 -1.05457743871052E-06"
        rpy="0 0 0" />
      <mass
        value="0.756902811678234" />
      <inertia
        ixx="0.000489881998551559"
        ixy="3.58229223155508E-07"
        ixz="-1.00636824395393E-07"
        iyy="0.00877497082161812"
        iyz="-9.58230053462793E-09"
        izz="0.00836333501590687" />
    </inertial>
    <visual>
      <origin
        xyz="0 0 0"
        rpy="0 0 0" />
      <geometry>
        <mesh
          filename="package://tracked_robot/meshes/Flipper_R.STL" />
      </geometry>
      <material
        name="">
        <color
          rgba="0.752941176470588 0.752941176470588 0.752941176470588 1" />
      </material>
    </visual>
    <collision>
      <origin
        xyz="0 0 0"
        rpy="0 0 0" />
      <geometry>
        <mesh
          filename="package://tracked_robot/meshes/Flipper_R.STL" />
      </geometry>
    </collision>
  </link>
  <joint
    name="Joint_R"
    type="continuous">
    <origin
      xyz="0.3 -0.04 0"
      rpy="0 0 0" />
    <parent
      link="Track_R" />
    <child
      link="Flipper_R" />
    <axis
      xyz="0 -1 0" />
    <limit
      effort="10000"
      velocity="0" />
  </joint>
</robot>